try:
  raise Exception("foo")
except:
  print("exception")
